<?xml version="1.0"?>
<!-- created with Phobos 0.7 -->
  <robot name="dji_arms_exported_urdf">

    <link name="armL_bfinger">
      <inertial>
        <origin xyz="0 0 0" rpy="0 0 0"/>
        <mass value="0.05426"/>
        <inertia ixx="0.001" ixy="0" ixz="0" iyy="0.001" iyz="0" izz="0.001"/>
      </inertial>
      <visual name="visual_0_armL_bfinger">
        <origin xyz="0 0 0" rpy="0 0 0"/>
        <geometry>
          <mesh filename="../meshes/obj/armL bfinger.obj" scale="1.0 1.0 1.0"/>
        </geometry>
      </visual>
      <collision name="collision_0_armL_bfinger">
        <origin xyz="0 0 0" rpy="0 0 0"/>
        <geometry>
          <mesh filename="../meshes/obj/armL bfinger.001.obj" scale="1.0 1.0 1.0"/>
        </geometry>
      </collision>
    </link>

    <link name="armL_hand">
      <inertial>
        <origin xyz="0 0 0" rpy="0 0 0"/>
        <mass value="0.51528"/>
        <inertia ixx="0.001" ixy="-2e-05" ixz="0" iyy="0.001" iyz="0" izz="0.001"/>
      </inertial>
      <visual name="visual_0_armL_hand">
        <origin xyz="0 0 0" rpy="0 0 0"/>
        <geometry>
          <mesh filename="../meshes/obj/armL hand.002.obj" scale="1.0 1.0 1.0"/>
        </geometry>
        <material name="hand_blue"/>
      </visual>
      <collision name="collision_0_armL_hand">
        <origin xyz="0 0 0" rpy="0 0 0"/>
        <geometry>
          <mesh filename="../meshes/obj/armL hand.003.obj" scale="1.0 1.0 1.0"/>
        </geometry>
      </collision>
    </link>

    <link name="armL_link1">
      <inertial>
        <origin xyz="0 0 0" rpy="0 0 0"/>
        <mass value="0.29699"/>
        <inertia ixx="0.001" ixy="0" ixz="0" iyy="0.001" iyz="-2e-05" izz="0.001"/>
      </inertial>
      <visual name="visual_0_armL_link1">
        <origin xyz="0 0 0" rpy="0 0 0"/>
        <geometry>
          <mesh filename="../meshes/obj/armL link1.002.obj" scale="1.0 1.0 1.0"/>
        </geometry>
        <material name="arm_beige"/>
      </visual>
      <collision name="collision_0_armL_link1">
        <origin xyz="0 0 0" rpy="0 0 0"/>
        <geometry>
          <mesh filename="../meshes/obj/armL link1.003.obj" scale="1.0 1.0 1.0"/>
        </geometry>
      </collision>
    </link>

    <link name="armL_link2">
      <inertial>
        <origin xyz="0 0 0" rpy="0 0 0"/>
        <mass value="0.43522"/>
        <inertia ixx="0.00442" ixy="0" ixz="0" iyy="0.001" iyz="0" izz="0.00438"/>
      </inertial>
      <visual name="visual_0_armL_link2">
        <origin xyz="0 0 0" rpy="0 0 0"/>
        <geometry>
          <mesh filename="../meshes/obj/armL link2.obj" scale="1.0 1.0 1.0"/>
        </geometry>
      </visual>
      <collision name="collision_0_armL_link2">
        <origin xyz="0 0 0" rpy="0 0 0"/>
        <geometry>
          <mesh filename="../meshes/obj/armL link2.001.obj" scale="1.0 1.0 1.0"/>
        </geometry>
      </collision>
    </link>

    <link name="armL_link3">
      <inertial>
        <origin xyz="0 0 0" rpy="0 0 0"/>
        <mass value="0.40456"/>
        <inertia ixx="0.00113" ixy="0" ixz="0" iyy="0.001" iyz="8e-05" izz="0.00112"/>
      </inertial>
      <visual name="visual_0_armL_link3">
        <origin xyz="0 0 0" rpy="0 0 0"/>
        <geometry>
          <mesh filename="../meshes/obj/armL link3.obj" scale="1.0 1.0 1.0"/>
        </geometry>
      </visual>
      <collision name="collision_0_armL_link3">
        <origin xyz="0 0 0" rpy="0 0 0"/>
        <geometry>
          <mesh filename="../meshes/obj/armL link3.001.obj" scale="1.0 1.0 1.0"/>
        </geometry>
      </collision>
    </link>

    <link name="armL_tfinger">
      <inertial>
        <origin xyz="0 0 0" rpy="0 0 0"/>
        <mass value="0.10851"/>
        <inertia ixx="0.001" ixy="1e-05" ixz="0" iyy="0.001" iyz="0" izz="0.001"/>
      </inertial>
      <visual name="visual_0_armL_tfinger">
        <origin xyz="0 0 0" rpy="0 0 0"/>
        <geometry>
          <mesh filename="../meshes/obj/armL tfinger.002.obj" scale="1.0 1.0 1.0"/>
        </geometry>
        <material name="finger_purple"/>
      </visual>
      <collision name="collision_0_armL_tfinger">
        <origin xyz="0 0 0" rpy="0 0 0"/>
        <geometry>
          <mesh filename="../meshes/obj/armL tfinger.003.obj" scale="1.0 1.0 1.0"/>
        </geometry>
      </collision>
    </link>

    <link name="armR_bfinger">
      <inertial>
        <origin xyz="0 0 0" rpy="0 0 0"/>
        <mass value="0.05426"/>
        <inertia ixx="0.001" ixy="0" ixz="0" iyy="0.001" iyz="0" izz="0.001"/>
      </inertial>
      <visual name="visual_0_armR_bfinger">
        <origin xyz="0 0 0" rpy="0 0 0"/>
        <geometry>
          <mesh filename="../meshes/obj/armL bfinger.002.obj" scale="1.0 1.0 1.0"/>
        </geometry>
      </visual>
      <collision name="collision_0_armR_bfinger">
        <origin xyz="0 0 0" rpy="0 0 0"/>
        <geometry>
          <mesh filename="../meshes/obj/armL bfinger.003.obj" scale="1.0 1.0 1.0"/>
        </geometry>
      </collision>
    </link>

    <link name="armR_hand">
      <inertial>
        <origin xyz="0 0 0" rpy="0 0 0"/>
        <mass value="0.51528"/>
        <inertia ixx="0.001" ixy="-2e-05" ixz="0" iyy="0.001" iyz="0" izz="0.001"/>
      </inertial>
      <visual name="visual_0_armR_hand">
        <origin xyz="0 0 0" rpy="0 0 0"/>
        <geometry>
          <mesh filename="../meshes/obj/armL hand.obj" scale="1.0 1.0 1.0"/>
        </geometry>
      </visual>
      <collision name="collision_0_armR_hand">
        <origin xyz="0 0 0" rpy="0 0 0"/>
        <geometry>
          <mesh filename="../meshes/obj/armL hand.001.obj" scale="1.0 1.0 1.0"/>
        </geometry>
      </collision>
    </link>

    <link name="armR_link1">
      <inertial>
        <origin xyz="0 0 0" rpy="0 0 0"/>
        <mass value="0.29699"/>
        <inertia ixx="0.001" ixy="0" ixz="0" iyy="0.001" iyz="-2e-05" izz="0.001"/>
      </inertial>
      <visual name="visual_0_armR_link1">
        <origin xyz="0 0 0" rpy="0 0 0"/>
        <geometry>
          <mesh filename="../meshes/obj/armL link1.obj" scale="1.0 1.0 1.0"/>
        </geometry>
      </visual>
      <collision name="collision_0_armR_link1">
        <origin xyz="0 0 0" rpy="0 0 0"/>
        <geometry>
          <mesh filename="../meshes/obj/armL link1.001.obj" scale="1.0 1.0 1.0"/>
        </geometry>
      </collision>
    </link>

    <link name="armR_link2">
      <inertial>
        <origin xyz="0 0 0" rpy="0 0 0"/>
        <mass value="0.43522"/>
        <inertia ixx="0.00442" ixy="0" ixz="0" iyy="0.001" iyz="0" izz="0.00438"/>
      </inertial>
      <visual name="visual_0_armR_link2">
        <origin xyz="0 0 0" rpy="0 0 0"/>
        <geometry>
          <mesh filename="../meshes/obj/armL link2.002.obj" scale="1.0 1.0 1.0"/>
        </geometry>
      </visual>
      <collision name="collision_0_armR_link2">
        <origin xyz="0 0 0" rpy="0 0 0"/>
        <geometry>
          <mesh filename="../meshes/obj/armL link2.003.obj" scale="1.0 1.0 1.0"/>
        </geometry>
      </collision>
    </link>

    <link name="armR_link3">
      <inertial>
        <origin xyz="0 0 0" rpy="0 0 0"/>
        <mass value="0.40456"/>
        <inertia ixx="0.00113" ixy="0" ixz="0" iyy="0.001" iyz="8e-05" izz="0.00112"/>
      </inertial>
      <visual name="visual_0_armR_link3">
        <origin xyz="0 0 0" rpy="0 0 0"/>
        <geometry>
          <mesh filename="../meshes/obj/armL link3.002.obj" scale="1.0 1.0 1.0"/>
        </geometry>
      </visual>
      <collision name="collision_0_armR_link3">
        <origin xyz="0 0 0" rpy="0 0 0"/>
        <geometry>
          <mesh filename="../meshes/obj/armL link3.003.obj" scale="1.0 1.0 1.0"/>
        </geometry>
      </collision>
    </link>

    <link name="armR_tfinger">
      <inertial>
        <origin xyz="0 0 0" rpy="0 0 0"/>
        <mass value="0.10851"/>
        <inertia ixx="0.001" ixy="1e-05" ixz="0" iyy="0.001" iyz="0" izz="0.001"/>
      </inertial>
      <visual name="visual_0_armR_tfinger">
        <origin xyz="0 0 0" rpy="0 0 0"/>
        <geometry>
          <mesh filename="../meshes/obj/armL tfinger.obj" scale="1.0 1.0 1.0"/>
        </geometry>
      </visual>
      <collision name="collision_0_armR_tfinger">
        <origin xyz="0 0 0" rpy="0 0 0"/>
        <geometry>
          <mesh filename="../meshes/obj/armL tfinger.001.obj" scale="1.0 1.0 1.0"/>
        </geometry>
      </collision>
    </link>

    <link name="dji_hexcopter">
      <inertial>
        <origin xyz="0 0 0" rpy="0 0 0"/>
        <mass value="1.8786"/>
        <inertia ixx="0.00376" ixy="0" ixz="0" iyy="0.00479" iyz="0" izz="0.00173"/>
      </inertial>
      <visual name="visual_0_dji_hexcopter">
        <origin xyz="0 0 0" rpy="0 0 0"/>
        <geometry>
          <mesh filename="../meshes/obj/dji hexcopter.obj" scale="1.0 1.0 1.0"/>
        </geometry>
        <material name="hexcopter_red"/>
      </visual>
      <collision name="collision_0_dji_hexcopter">
        <origin xyz="0 0 0" rpy="0 0 0"/>
        <geometry>
          <mesh filename="../meshes/obj/dji hexcopter.001.obj" scale="1.0 1.0 1.0"/>
        </geometry>
      </collision>
    </link>

    <joint name="armL_joint1" type="continuous">
      <origin xyz="0.09567 -0.02984 -0.0907" rpy="-1.1425 0 -1.5708"/>
      <parent link="dji_hexcopter"/>
      <child link="armL_link1"/>
      <axis xyz="0 1.0 0"/>
      <limit effort="0" velocity="0"/>
    </joint>

    <joint name="armL_joint2" type="continuous">
      <origin xyz="0 0.06133 -0.0677" rpy="0 0 0"/>
      <parent link="armL_link1"/>
      <child link="armL_link2"/>
      <axis xyz="0 0 1.0"/>
    </joint>

    <joint name="armL_joint3" type="continuous">
      <origin xyz="0 0.2125 -0.02883" rpy="0 0 0"/>
      <parent link="armL_link2"/>
      <child link="armL_link3"/>
      <axis xyz="0 0 1.0"/>
    </joint>

    <joint name="armL_joint_bfinger" type="continuous">
      <origin xyz="0.03336 0.05794 0" rpy="0 0 0"/>
      <parent link="armL_hand"/>
      <child link="armL_bfinger"/>
      <axis xyz="0 0 1.0"/>
    </joint>

    <joint name="armL_joint_tfinger" type="continuous">
      <origin xyz="-0.0334 0.05794 0" rpy="0 0 0"/>
      <parent link="armL_hand"/>
      <child link="armL_tfinger"/>
      <axis xyz="0 0 1.0"/>
    </joint>

    <joint name="armL_joint_wrist" type="continuous">
      <origin xyz="0 0.18481 0.09983" rpy="-0.03467 1.57079 -0.04367"/>
      <parent link="armL_link3"/>
      <child link="armL_hand"/>
      <axis xyz="0 1.0 0"/>
    </joint>

    <joint name="armR_joint1" type="continuous">
      <origin xyz="-0.07921 -0.02984 -0.04819" rpy="-1.1425 0 1.5708"/>
      <parent link="dji_hexcopter"/>
      <child link="armR_link1"/>
      <axis xyz="0 1.0 0"/>
    </joint>

    <joint name="armR_joint2" type="continuous">
      <origin xyz="0 0.10806 0.04894" rpy="0 0 0"/>
      <parent link="armR_link1"/>
      <child link="armR_link2"/>
      <axis xyz="0 0 1.0"/>
    </joint>

    <joint name="armR_joint3" type="continuous">
      <origin xyz="0 0.2125 0" rpy="0 0 0"/>
      <parent link="armR_link2"/>
      <child link="armR_link3"/>
      <axis xyz="0 0 1.0"/>
    </joint>

    <joint name="armR_joint_bfinger" type="continuous">
      <origin xyz="0.03336 0.10959 0" rpy="0 0 0"/>
      <parent link="armR_hand"/>
      <child link="armR_bfinger"/>
      <axis xyz="0 0 1.0"/>
    </joint>

    <joint name="armR_joint_tfinger" type="continuous">
      <origin xyz="-0.0334 0.10959 0" rpy="0 0 0"/>
      <parent link="armR_hand"/>
      <child link="armR_tfinger"/>
      <axis xyz="0 0 1.0"/>
    </joint>

    <joint name="armR_joint_wrist" type="continuous">
      <origin xyz="0 0.13316 -0.04564" rpy="-0.03466 1.57079 -0.0261"/>
      <parent link="armR_link3"/>
      <child link="armR_hand"/>
      <axis xyz="0 1.0 0"/>
    </joint>

    <material name="arm_beige">
      <color rgba="0.94509 0.79215 0.72941 1.0"/>
    </material>

    <material name="finger_purple">
      <color rgba="0.54901 0.38823 0.81176 1.0"/>
    </material>

    <material name="hand_blue">
      <color rgba="0.2 0.67843 0.8 1.0"/>
    </material>

    <material name="hexcopter_red">
      <color rgba="0.7098 0.18823 0.14117 1.0"/>
    </material>

  </robot>
