<?xml version="1.0" ?>

<robot name="rprbot">

    <link name="base_link">
        <inertial>
            <origin xyz="0.0 0.0 0.0" rpy="0 0 0" />
            <mass value="0.01" />
            <inertia ixx="0.0000001" iyy="0.0000001" izz="0.0000001" ixy="0" ixz="0" iyz="0" />
        </inertial>
        <visual>
            <origin xyz="0.0 0.0 -0.1" rpy="0 0 0" />
            <geometry>
                <box size="10 10 0.05" />
            </geometry>
            <material name="material_gray">
                <color rgba="0.1 0.1 0.1 1.0" />
            </material>
        </visual>
    </link>

    <link name="link0">
        <inertial>
            <origin xyz="0.0 0.0 0.0" rpy="0 0 0" />
            <mass value="0.01" />
            <inertia ixx="0.0000001" iyy="0.0000001" izz="0.0000001" ixy="0" ixz="0" iyz="0" />
        </inertial>
        <visual>
            <origin xyz="0.0 0.0 0.0" rpy="0 0 0" />
            <geometry>
                <cylinder radius="0.06" length="0.15"/>
            </geometry>
            <material name="material_blue">
                <color rgba="0.3 0.3 0.9 1.0" />
            </material>
        </visual>
    </link>

    <link name="link1">
        <inertial>
            <origin xyz="0.0 0.0 0.0" rpy="0 0 0" />
            <mass value="0.01" />
            <inertia ixx="0.0000001" iyy="0.0000001" izz="0.0000001" ixy="0" ixz="0" iyz="0" />
        </inertial>
        <visual>
            <origin xyz="0.0 0.0 -2.5" rpy="0 0 0" />
            <geometry>
                <cylinder radius="0.03" length="2.5"/>
            </geometry>
        </visual>
        <visual>
            <origin xyz="0.0 0.0 -0.15" rpy="0 0 0" />
            <geometry>
                <box size="0.1 0.15 0.05"/>
            </geometry>
            <material name="material_blue">
                <color rgba="0.3 0.3 0.9 1.0" />
            </material>
        </visual>
        <visual>
            <origin xyz="0.075 0.0 0.0" rpy="0 -1.57079632679 0" />
            <geometry>
                <cylinder radius="0.06" length="0.15"/>
            </geometry>
            <material name="material_blue">
                <color rgba="0.3 0.3 0.9 1.0" />
            </material>
        </visual>
    </link>

    <link name="link2">
        <inertial>
            <origin xyz="0.0 0.0 1.5" rpy="0 0 0" />
            <mass value="1" />
            <inertia ixx="0.0000001" iyy="0.0000001" izz="0.0000001" ixy="0" ixz="0" iyz="0" />
        </inertial>
        <visual>
            <origin xyz="0.0 0.0 0.0" rpy="0 0 0" />
            <geometry>
                <cylinder radius="0.03" length="1.5"/>
            </geometry>
        </visual>
        <visual>
            <origin xyz="0.0 0.0 1.5" rpy="0 0 0" />
            <geometry>
                <sphere radius="0.09" />
            </geometry>
            <material name="material_red">
		        <color rgba="0.5 0.0 0.0 1.0" />
	        </material>
        </visual>

    </link>
    
    <joint name="j0" type="revolute">
        <parent link="base_link" />
        <child link="link0" />
        <origin xyz="0 0 0" rpy="0.523599 0 0" />
        <axis xyz="0 0 1" />
        <limit lower="-2.967" upper="2.967" effort="176" velocity="1.7104" />
    </joint>

    <joint name="j1" type="prismatic">
        <parent link="link0" />
        <child link="link1" />
        <origin xyz="0 0 0" rpy="0 0 0" />
        <axis xyz="0 0 1" />
        <limit lower="-2.967" upper="2.967" effort="176" velocity="1.7104" />
    </joint>

    <joint name="j2" type="revolute">
        <parent link="link1" />
        <child link="link2" />
        <origin xyz="0 0 0" rpy="0 0 0" />
        <axis xyz="1 0 0" />
        <limit lower="-2.967" upper="2.967" effort="176" velocity="1.7104" />
    </joint>
    
</robot>


