<?xml version='1.0' encoding='utf-8'?>

<robot name="mmp_panda" version="1.0">

  <!-- GROUND LINK -->
  <link name ="ground_link">
    <inertial>
      <origin xyz="0.0 0.0 0.0" rpy="0 0 0" />
      <mass value="0.001" />
      <inertia ixx="1E-06" ixy="0.0" ixz="0.0" iyy="1E-06" iyz="0.0" izz="1E-06" />
    </inertial>
  </link>


  <!-- MOBILE BASE LINKS -->
  <link name ="base_x">
    <inertial>
      <origin xyz="0.0 0.0 0.0" rpy="0 0 0" />
      <mass value="0.001" />
      <inertia ixx="1E-06" ixy="0.0" ixz="0.0" iyy="1E-06" iyz="0.0" izz="1E-06" />
    </inertial>
  </link>

  <link name = "base_y">
    <inertial>
      <origin xyz="0.0 0.0 0.0" rpy="0 0 0" />
      <mass value = "0.001" />
      <inertia ixx="1E-06" ixy="0.0" ixz="0.0" iyy="1E-06" iyz="0.0" izz="1E-06" />
    </inertial>
  </link>

  <!-- MOBILE BASE + LINK 0 OF PANDA ARM -->
  <link name = "base_link">
    <inertial>
      <origin xyz="0.0 0.0 0.1757" rpy="0 0 0" />
      <mass value = "64.6" />
      <inertia ixx="1.721" ixy="0.0" ixz="0.0" iyy="1.712" iyz="0.0" izz="2.030" />
    </inertial>
    <visual>
      <geometry>
        <mesh filename="../../../model/mmp_two_arm_panda/meshes/mmp_panda_two_arm_base.obj" />
      </geometry>
    </visual>
  </link>

  <!-- PANDA LEFT ARM LINKS --> 
<!--<link name="link0">
    <inertial>
      <origin xyz="0 0 0.05" rpy="0 0 0" />
      <mass value="4" />
      <inertia ixx="0.4" iyy="0.4" izz="0.4" ixy="0" ixz="0" iyz="0" />
    </inertial>
    <visual>
      <geometry>
        <mesh filename="../../../model/panda/meshes/visual/link0.obj"/>
      </geometry>
    </visual>
<!      <collision>
        <geometry>
          <mesh filename="../../../model/panda/meshes/collision/link0.obj"/>
        </geometry>
      </collision> 
  </link> -->
  <link name="link1_left">
    <inertial>
      <origin xyz="0 0 -0.07" rpy="0 -0 0" />
      <mass value="4" />
      <inertia ixx="0.3" iyy="0.3" izz="0.3" ixy="0" ixz="0" iyz="0" />
    </inertial>
    <visual>
      <geometry>
        <mesh filename="../../../model/panda/meshes/visual/link1.obj"/>
      </geometry>
    </visual>
    <!-- <collision>
      <geometry>
        <mesh filename="../../../model/panda/meshes/collision/link1.obj"/>
      </geometry>
    </collision> -->
  </link>
  <link name="link2_left">
    <inertial>
      <origin xyz="0 -0.1 0" rpy="0 -0 0" />
      <mass value="3" />
      <inertia ixx="0.3" iyy="0.3" izz="0.3" ixy="0" ixz="0" iyz="0" />
    </inertial>
    <visual>
      <geometry>
        <mesh filename="../../../model/panda/meshes/visual/link2.obj"/>
      </geometry>
    </visual>
    <!-- <collision>
      <geometry>
        <mesh filename="../../../model/panda/meshes/collision/link2.obj"/>
      </geometry>
    </collision> -->
  </link>
  <link name="link3_left">
    <inertial>
      <origin xyz="0.04 0 -0.05" rpy="0 -0 0" />
      <mass value="3" />
      <inertia ixx="0.2" iyy="0.2" izz="0.2" ixy="0" ixz="0" iyz="0" />
    </inertial>
    <visual>
      <geometry>
        <mesh filename="../../../model/panda/meshes/visual/link3.obj"/>
      </geometry>
    </visual>
    <!-- <collision>
      <geometry>
        <mesh filename="../../../model/panda/meshes/collision/link3.obj"/>
      </geometry>
    </collision> -->
  </link>
  <link name="link4_left">
    <inertial>
      <origin xyz="-0.04 0.05 0" rpy="0 -0 0" />
      <mass value="3" />
      <inertia ixx="0.2" iyy="0.2" izz="0.2" ixy="0" ixz="0" iyz="0" />
    </inertial>
    <visual>
      <geometry>
        <mesh filename="../../../model/panda/meshes/visual/link4.obj"/>
      </geometry>
    </visual>
<!--       <collision>
      <geometry>
        <mesh filename="../../../model/panda/meshes/collision/link4.obj"/>
      </geometry>
    </collision> -->
  </link>
  <link name="link5_left">
    <inertial>
      <origin xyz="0 0 -0.15" rpy="0 -0 0" />
      <mass value="3" />
      <inertia ixx="0.2" iyy="0.2" izz="0.2" ixy="0" ixz="0" iyz="0" />
    </inertial>
    <visual>
      <geometry>
        <mesh filename="../../../model/panda/meshes/visual/link5.obj"/>
      </geometry>
    </visual>
<!--       <collision>
      <geometry>
        <mesh filename="../../../model/panda/meshes/collision/link5.obj"/>
      </geometry>
    </collision> -->
  </link>
  <link name="link6_left">
    <inertial>
      <origin xyz="0.06 0 0" rpy="0 -0 0" />
      <mass value="2" />
      <inertia ixx="0.1" iyy="0.1" izz="0.1" ixy="0" ixz="0" iyz="0" />
    </inertial>
    <visual>
      <geometry>
        <mesh filename="../../../model/panda/meshes/visual/link6.obj"/>
      </geometry>
    </visual>
    <!-- <collision>
      <geometry>
        <mesh filename="../../../model/panda/meshes/collision/link6.obj"/>
      </geometry>
    </collision> -->
  </link>
  <link name="link7_left">
    <inertial>
      <origin xyz="0 0 0.17" rpy="0 -0 0" />
      <mass value="3.0" />
      <inertia ixx="0.09" iyy="0.05" izz="0.07" ixy="0" ixz="0" iyz="0" />
    </inertial>
    <visual>
      <geometry>
        <mesh filename="../../../model/panda/meshes/visual/link7.obj"/>
      </geometry>
    </visual>
    <!-- <collision>
      <geometry>
        <mesh filename="../../../model/panda/meshes/collision/link7.obj"/>
      </geometry>
    </collision> -->
  </link>

  <!--PANDA RIGHT ARM LINK-->

    <link name="link1_right">
    <inertial>
      <origin xyz="0 0 -0.07" rpy="0 -0 0" />
      <mass value="4" />
      <inertia ixx="0.3" iyy="0.3" izz="0.3" ixy="0" ixz="0" iyz="0" />
    </inertial>
    <visual>
      <geometry>
        <mesh filename="../../../model/panda/meshes/visual/link1.obj"/>
      </geometry>
    </visual>
    <!-- <collision>
      <geometry>
        <mesh filename="../../../model/panda/meshes/collision/link1.obj"/>
      </geometry>
    </collision> -->
  </link>
  <link name="link2_right">
    <inertial>
      <origin xyz="0 -0.1 0" rpy="0 -0 0" />
      <mass value="3" />
      <inertia ixx="0.3" iyy="0.3" izz="0.3" ixy="0" ixz="0" iyz="0" />
    </inertial>
    <visual>
      <geometry>
        <mesh filename="../../../model/panda/meshes/visual/link2.obj"/>
      </geometry>
    </visual>
    <!-- <collision>
      <geometry>
        <mesh filename="../../../model/panda/meshes/collision/link2.obj"/>
      </geometry>
    </collision> -->
  </link>
  <link name="link3_right">
    <inertial>
      <origin xyz="0.04 0 -0.05" rpy="0 -0 0" />
      <mass value="3" />
      <inertia ixx="0.2" iyy="0.2" izz="0.2" ixy="0" ixz="0" iyz="0" />
    </inertial>
    <visual>
      <geometry>
        <mesh filename="../../../model/panda/meshes/visual/link3.obj"/>
      </geometry>
    </visual>
    <!-- <collision>
      <geometry>
        <mesh filename="../../../model/panda/meshes/collision/link3.obj"/>
      </geometry>
    </collision> -->
  </link>
  <link name="link4_right">
    <inertial>
      <origin xyz="-0.04 0.05 0" rpy="0 -0 0" />
      <mass value="3" />
      <inertia ixx="0.2" iyy="0.2" izz="0.2" ixy="0" ixz="0" iyz="0" />
    </inertial>
    <visual>
      <geometry>
        <mesh filename="../../../model/panda/meshes/visual/link4.obj"/>
      </geometry>
    </visual>
<!--       <collision>
      <geometry>
        <mesh filename="../../../model/panda/meshes/collision/link4.obj"/>
      </geometry>
    </collision> -->
  </link>
  <link name="link5_right">
    <inertial>
      <origin xyz="0 0 -0.15" rpy="0 -0 0" />
      <mass value="3" />
      <inertia ixx="0.2" iyy="0.2" izz="0.2" ixy="0" ixz="0" iyz="0" />
    </inertial>
    <visual>
      <geometry>
        <mesh filename="../../../model/panda/meshes/visual/link5.obj"/>
      </geometry>
    </visual>
<!--       <collision>
      <geometry>
        <mesh filename="../../../model/panda/meshes/collision/link5.obj"/>
      </geometry>
    </collision> -->
  </link>
  <link name="link6_right">
    <inertial>
      <origin xyz="0.06 0 0" rpy="0 -0 0" />
      <mass value="2" />
      <inertia ixx="0.1" iyy="0.1" izz="0.1" ixy="0" ixz="0" iyz="0" />
    </inertial>
    <visual>
      <geometry>
        <mesh filename="../../../model/panda/meshes/visual/link6.obj"/>
      </geometry>
    </visual>
    <!-- <collision>
      <geometry>
        <mesh filename="../../../model/panda/meshes/collision/link6.obj"/>
      </geometry>
    </collision> -->
  </link>
  <link name="link7_right">
    <inertial>
      <origin xyz="0 0 0.17" rpy="0 -0 0" />
      <mass value="3.0" />
      <inertia ixx="0.09" iyy="0.05" izz="0.07" ixy="0" ixz="0" iyz="0" />
    </inertial>
    <visual>
      <geometry>
        <mesh filename="../../../model/panda/meshes/visual/link7.obj"/>
      </geometry>
    </visual>
    <!-- <collision>
      <geometry>
        <mesh filename="../../../model/panda/meshes/collision/link7.obj"/>
      </geometry>
    </collision> -->
  </link>


  <!-- JOINTS -->
  <joint name = "base_prismatic_x" type = "prismatic">
    <origin xyz = "0 0 0" rpy = "0 0 0"/> 
    <parent link = "ground_link" />
    <child link= "base_x"/>
    <axis xyz = "1 0 0" />
    <limit effort="87" lower="-2.8973" upper="2.9873" velocity="2.1750" />
  </joint>

  <joint name = "base_prismatic_y" type = "prismatic">
    <origin xyz = "0 0 0" rpy = "0 0 0"/> 
    <parent link = "base_x" />
    <child link= "base_y"/>
    <axis xyz = "0 1 0" />
    <limit effort="87" lower="-2.8973" upper="2.9873" velocity="2.1750" />
  </joint>

  <joint name = "base_revolute" type = "revolute">
    <origin xyz = "0 0 0.0" rpy = "0 0 0"/> 
    <parent link = "base_y" />
    <child link= "base_link"/>
    <axis xyz = "0 0 1" />
    <limit effort="87" lower="-2.8973" upper="2.8973" velocity="2.1750" />
  </joint>
<!--
  <joint name = "base_prismatic_link0" type = "prismatic">
    <origin xyz = "0 0 0.33" rpy = "0 0 0"/> 
    <parent link = "base_link" />
    <child link= "link0"/>
    <axis xyz = "0 0 1" />
    <limit effort="87" lower="-2.8973" upper="2.8973" velocity="2.1750" />
  </joint>
-->

<!--Left Arm Joints-->
  <joint name="joint1_left" type="revolute">
      <safety_controller k_position="100.0" k_velocity="40.0" soft_lower_limit="-2.8973" soft_upper_limit="2.8973"/>
      <origin rpy="0 0 1.5708" xyz="0 0.18 0.749"/>
      <parent link="base_link"/>
      <child link="link1_left"/>
      <axis xyz="0 0 1"/>
      <calibration falling="-80.0" />
      <limit effort="87" lower="-2.8973" upper="2.8973" velocity="2.1750"/>
  </joint>
  <joint name="joint2_left" type="revolute">
      <safety_controller k_position="100.0" k_velocity="40.0" soft_lower_limit="-1.7628" soft_upper_limit="1.7628"/>
      <origin rpy="-1.57079632679 0 0" xyz="0 0 0"/>
      <parent link="link1_left"/>
      <child link="link2_left"/>
      <axis xyz="0 0 1"/>
      <calibration falling="-45.0" />
      <limit effort="87" lower="-1.7628" upper="1.7628" velocity="2.1750"/>
  </joint>

  <joint name="joint3_left" type="revolute">
      <safety_controller k_position="100.0" k_velocity="40.0" soft_lower_limit="-2.8973" soft_upper_limit="2.8973"/>
      <origin rpy="1.57079632679 0 0" xyz="0 -0.316 0"/>
      <parent link="link2_left"/>
      <child link="link3_left"/>
      <axis xyz="0 0 1"/>
      <limit effort="87" lower="-2.8973" upper="2.8973" velocity="2.1750"/>
  </joint>

  <joint name="joint4_left" type="revolute">
      <safety_controller k_position="100.0" k_velocity="40.0" soft_lower_limit="-3.0718" soft_upper_limit="-0.0698"/>
      <origin rpy="1.57079632679 0 0" xyz="0.0825 0 0"/>
      <parent link="link3_left"/>
      <child link="link4_left"/>
      <axis xyz="0 0 1"/>
      <calibration falling="-125.0" />
      <limit effort="87" lower="-3.0718" upper="-0.0698" velocity="2.1750"/>
  </joint>

  <joint name="joint5_left" type="revolute">
      <safety_controller k_position="100.0" k_velocity="40.0" soft_lower_limit="-2.8973" soft_upper_limit="2.8973"/>
      <origin rpy="-1.57079632679 0 0" xyz="-0.0825 0.384 0"/>
      <parent link="link4_left"/>
      <child link="link5_left"/>
      <axis xyz="0 0 1"/>
      <limit effort="12" lower="-2.8973" upper="2.8973" velocity="2.6100"/>
  </joint>

  <joint name="joint6_left" type="revolute">
      <safety_controller k_position="100.0" k_velocity="40.0" soft_lower_limit="-0.0175" soft_upper_limit="3.7525"/>
      <origin rpy="1.57079632679 0 0" xyz="0 0 0"/>
      <parent link="link5_left"/>
      <child link="link6_left"/>
      <axis xyz="0 0 1"/>
      <calibration falling="80.0" />
      <limit effort="12" lower="-0.0175" upper="3.7525" velocity="2.6100"/>
  </joint>

  <joint name="joint7_left" type="revolute">
      <safety_controller k_position="100.0" k_velocity="40.0" soft_lower_limit="-2.8973" soft_upper_limit="2.8973"/>
      <origin rpy="1.57079632679 0 0" xyz="0.088 0 0"/>
      <parent link="link6_left"/>
      <child link="link7_left"/>
      <axis xyz="0 0 1"/>
      <limit effort="12" lower="-2.8973" upper="2.8973" velocity="2.6100"/>
  </joint>


  <!--Right Arm Joints-->
  <joint name="joint1_right" type="revolute">
      <safety_controller k_position="100.0" k_velocity="40.0" soft_lower_limit="-2.8973" soft_upper_limit="2.8973"/>
      <origin rpy="0 0 1.5708" xyz="0 -0.18 0.749"/>
      <parent link="base_link"/>
      <child link="link1_right"/>
      <axis xyz="0 0 1"/>
      <calibration falling="-80.0" />
      <limit effort="87" lower="-2.8973" upper="2.8973" velocity="2.1750"/>
  </joint>
  <joint name="joint2_right" type="revolute">
      <safety_controller k_position="100.0" k_velocity="40.0" soft_lower_limit="-1.7628" soft_upper_limit="1.7628"/>
      <origin rpy="-1.57079632679 0 0" xyz="0 0 0"/>
      <parent link="link1_right"/>
      <child link="link2_right"/>
      <axis xyz="0 0 1"/>
      <calibration falling="-45.0" />
      <limit effort="87" lower="-1.7628" upper="1.7628" velocity="2.1750"/>
  </joint>

  <joint name="joint3_right" type="revolute">
      <safety_controller k_position="100.0" k_velocity="40.0" soft_lower_limit="-2.8973" soft_upper_limit="2.8973"/>
      <origin rpy="1.57079632679 0 0" xyz="0 -0.316 0"/>
      <parent link="link2_right"/>
      <child link="link3_right"/>
      <axis xyz="0 0 1"/>
      <limit effort="87" lower="-2.8973" upper="2.8973" velocity="2.1750"/>
  </joint>

  <joint name="joint4_right" type="revolute">
      <safety_controller k_position="100.0" k_velocity="40.0" soft_lower_limit="-3.0718" soft_upper_limit="-0.0698"/>
      <origin rpy="1.57079632679 0 0" xyz="0.0825 0 0"/>
      <parent link="link3_right"/>
      <child link="link4_right"/>
      <axis xyz="0 0 1"/>
      <calibration falling="-125.0" />
      <limit effort="87" lower="-3.0718" upper="-0.0698" velocity="2.1750"/>
  </joint>

  <joint name="joint5_right" type="revolute">
      <safety_controller k_position="100.0" k_velocity="40.0" soft_lower_limit="-2.8973" soft_upper_limit="2.8973"/>
      <origin rpy="-1.57079632679 0 0" xyz="-0.0825 0.384 0"/>
      <parent link="link4_right"/>
      <child link="link5_right"/>
      <axis xyz="0 0 1"/>
      <limit effort="12" lower="-2.8973" upper="2.8973" velocity="2.6100"/>
  </joint>

  <joint name="joint6_right" type="revolute">
      <safety_controller k_position="100.0" k_velocity="40.0" soft_lower_limit="-0.0175" soft_upper_limit="3.7525"/>
      <origin rpy="1.57079632679 0 0" xyz="0 0 0"/>
      <parent link="link5_right"/>
      <child link="link6_right"/>
      <axis xyz="0 0 1"/>
      <calibration falling="80.0" />
      <limit effort="12" lower="-0.0175" upper="3.7525" velocity="2.6100"/>
  </joint>

  <joint name="joint7_right" type="revolute">
      <safety_controller k_position="100.0" k_velocity="40.0" soft_lower_limit="-2.8973" soft_upper_limit="2.8973"/>
      <origin rpy="1.57079632679 0 0" xyz="0.088 0 0"/>
      <parent link="link6_right"/>
      <child link="link7_right"/>
      <axis xyz="0 0 1"/>
      <limit effort="12" lower="-2.8973" upper="2.8973" velocity="2.6100"/>
  </joint>

</robot> 