<?xml version="1.0" ?>

<robot name="rbot">

    <link name="base_link">
        <inertial>
            <origin xyz="0.0 0.0 0.0" rpy="0 0 0" />
            <mass value="0.01" />
            <inertia ixx="0.0000001" iyy="0.0000001" izz="0.0000001" ixy="0" ixz="0" iyz="0" />
        </inertial>
        <visual>
            <origin xyz="0.0 0.0 0.0" rpy="0 0 0" />
            <geometry>
                <box size="0.5 0.5 0.05" />
            </geometry>
        </visual>
    </link>

    <link name="link0">
        <inertial>
            <origin xyz="0.0 0.0 -1.0" rpy="0 0 0" />
            <mass value="0.5" />
            <inertia ixx="0.001" iyy="0.001" izz="0.001" ixy="0" ixz="0" iyz="0" />
        </inertial>
        <visual>
            <origin xyz="0.0 0.0 -0.5" rpy="0 0 0" />
            <geometry>
                <cylinder radius="0.05" length="0.5"/>
            </geometry>
            <material name="material_gray">
                <color rgba="0.3 0.3 0.5 1.0" />
            </material>
        </visual>
        <visual>
            <origin xyz="0.0 0.0 -0.5" rpy="0 0 0" />
            <geometry>
                <sphere radius="0.1"/>
            </geometry>
            <material name="material_gray">
                <color rgba="0.5 0.3 0.3 1.0" />
            </material>
        </visual>
    </link>

    
    <joint name="j0" type="revolute">
        <parent link="base_link" />
        <child link="link0" />
        <origin xyz="0.000000 0.000000 0.000000" rpy="-0.000000 0.000000 -0.000000" />
        <axis xyz="1 0 0" />
        <limit lower="-2.967" upper="2.967" effort="176" velocity="1.7104" />
    </joint>

    
</robot>


