<?xml version='1.0' encoding='utf-8'?>
<robot name="stanbot">

    <link name="right_foot">
      <inertial>
        <origin xyz="0 0 0" rpy="0 0 0" />
        <mass value="4" />
        <inertia ixx="0.4" iyy="0.4" izz="0.4" ixy="0" ixz="0" iyz="0" />
      </inertial>
      <visual>
        <geometry>
          <mesh filename="../../../model/stanbot/meshes/visual/foot.obj"/>
        </geometry>
      </visual>
      <!-- <visual>
        <origin xyz="0.0 0.0 0.0" rpy="0.0 0.0 0.0"/>
        <geometry>
            <sphere radius="0.05"/>
        </geometry>
      </visual> -->
    </link>

    <link name="right_calf">
      <inertial>
        <origin xyz="0 0 0.2" rpy="0 0 0" />
        <mass value="4" />
        <inertia ixx="0.3" iyy="0.3" izz="0.3" ixy="0" ixz="0" iyz="0" />
      </inertial>
      <visual>
        <origin xyz="0.0 0.0 0.22" rpy="0.0 0.0 0.0"/>
        <geometry>
          <mesh filename="../../../model/stanbot/meshes/visual/calf.obj"/>
        </geometry>
      </visual>
      <!-- <visual>
        <geometry>
          <sphere radius="0.01" />
        </geometry>
      </visual> -->
        <!-- <visual>
        <origin xyz="0.0 0.0 0.2" rpy="0.0 0.0 0.0"/>
        <geometry>
            <sphere radius="0.05"/>
        </geometry>
      </visual> -->
    </link>

    <link name="right_thigh">
      <inertial>
        <origin xyz="0 0 0.2" rpy="0 0 0" />
        <mass value="4" />
        <inertia ixx="0.3" iyy="0.3" izz="0.3" ixy="0" ixz="0" iyz="0" />
      </inertial>
      <visual>
        <origin xyz="0.0 0.0 0.2" rpy="0.0 0.0 0.0"/>
        <geometry>
          <mesh filename="../../../model/stanbot/meshes/visual/thigh.obj"/>
        </geometry>
      </visual>
      <!-- <visual>
        <origin xyz="0.0 0.0 0" rpy="0.0 0.0 0.0"/>
        <geometry>
          <sphere radius="0.05" />
        </geometry>
      </visual> -->
      <!-- <visual>
        <origin xyz="0.0 0.0 0.2" rpy="0.0 0.0 0.0"/>
        <geometry>
            <sphere radius="0.1"/>
        </geometry>
      </visual> -->
    </link>

    <link name="hip">
      <inertial>
        <origin xyz="0 0 0.2" rpy="0 0 0" />
        <mass value="4" />
        <inertia ixx="0.2" iyy="0.2" izz="0.2" ixy="0" ixz="0" iyz="0" />
      </inertial>
      <visual>
        <origin xyz="0.06 0 -0.05" rpy="0 0 0" />
        <geometry>
          <mesh filename="../../../model/stanbot/meshes/visual/hip_ascii.obj"/>
        </geometry>
      </visual>
      <!-- <visual>
        <origin xyz="0.0 0.0 0.0" rpy="0.0 0.0 0.0"/>
        <geometry>
          <sphere radius="0.05"/>
        </geometry>
      </visual> -->
    </link>

    <link name="chest">
      <inertial>
        <origin xyz="0 0 0.2" rpy="0 0 0" />
        <mass value="4" />
        <inertia ixx="0.2" iyy="0.2" izz="0.2" ixy="0" ixz="0" iyz="0" />
      </inertial>
      <visual>
      <origin xyz="0.0 0.0 -0.04" rpy="0.0 0.0 0.0"/>
        <geometry>
          <mesh filename="../../../model/stanbot/meshes/visual/chest_ascii.obj"/>
        </geometry>
      </visual>
    </link>

    <link name="left_thigh">
      <inertial>
        <origin xyz="0 0 -0.2" rpy="0 0 0" />
        <mass value="4" />
        <inertia ixx="0.2" iyy="0.2" izz="0.2" ixy="0" ixz="0" iyz="0" />
      </inertial>
      <visual>
        <origin xyz="0.0 0.0 -0.2" rpy="0.0 0.0 0.0"/>
        <geometry>
          <mesh filename="../../../model/stanbot/meshes/visual/thigh.obj"/>
        </geometry>
      </visual>
      <!-- <visual>
        <origin xyz="0.0 0.0 0.0" rpy="0.0 0.0 0.0"/>
        <geometry>
          <sphere radius="0.05"/>
        </geometry>
      </visual> -->
    <!-- <visual>
        <origin xyz="0.0 0.0 -0.2" rpy="0.0 0.0 0.0"/>
        <geometry>
            <sphere radius="0.1"/>
        </geometry>
      </visual> -->
    </link>

    <link name="left_calf">
      <inertial>
        <origin xyz="0 0 -0.2" rpy="0 0 0" />
        <mass value="4" />
        <inertia ixx="0.2" iyy="0.2" izz="0.2" ixy="0" ixz="0" iyz="0" />
      </inertial>
      <visual>
        <origin xyz="0.0 0.0 -0.18" rpy="0.0 0.0 0.0"/>
        <geometry>
          <mesh filename="../../../model/stanbot/meshes/visual/calf.obj"/>
        </geometry>
      </visual>
      <!-- <visual>
        <origin xyz="0.0 0.0 0.0" rpy="0.0 0.0 0.0"/>
        <geometry>
          <sphere radius="0.05"/>
        </geometry>
      </visual> -->
    </link>

    <link name="left_foot">
      <inertial>
        <origin xyz="0 0 0" rpy="0 0 0" />
        <mass value="4" />
        <inertia ixx="0.1" iyy="0.1" izz="0.1" ixy="0" ixz="0" iyz="0" />
      </inertial>
      <visual>
        <origin xyz="0 -0.03 -0.02" rpy="0.0 0.0 0.0"/>
        <geometry>
          <mesh filename="../../../model/stanbot/meshes/visual/foot.obj"/>
        </geometry>
      </visual>
      <!-- <visual>
        <origin xyz="0.0 0.0 0.0" rpy="0.0 0.0 0.0"/>
        <geometry>
          <sphere radius="0.05"/>
        </geometry>
      </visual> -->
    </link>

    <link name="head">
      <inertial>
        <origin xyz="0 0 0.2" rpy="0 0 0" />
        <mass value="0.5" />
        <inertia ixx="0.09" iyy="0.05" izz="0.07" ixy="0" ixz="0" iyz="0" />
      </inertial>
      <visual>
      <origin xyz="0.0 0.0 -0.02" rpy="0.0 0.0 0.0"/>
        <geometry>
          <mesh filename="../../../model/stanbot/meshes/visual/head_ascii.obj"/>
        </geometry>
      </visual>
    </link>

    <link name="right_upper_arm">
      <inertial>
        <origin xyz="0 0 -0.15" rpy="0 0 0" />
        <mass value="0.5" />
        <inertia ixx="0.09" iyy="0.05" izz="0.07" ixy="0" ixz="0" iyz="0" />
      </inertial>
      <visual>
        <geometry>
          <mesh filename="../../../model/stanbot/meshes/visual/upperArm_ascii.obj"/>
        </geometry>
      </visual>
        <!-- <visual>
        <origin xyz="0 0 -0.15" rpy="0.0 0.0 0.0"/>
        <geometry>
            <sphere radius="0.1"/>
        </geometry>
      </visual> -->
    </link>

    <link name="right_lower_arm">
      <inertial>
        <origin xyz="0 0 -0.15" rpy="0 0 0" />
        <mass value="0.5" />
        <inertia ixx="0.09" iyy="0.05" izz="0.07" ixy="0" ixz="0" iyz="0" />
      </inertial>
      <visual>
        <geometry>
          <mesh filename="../../../model/stanbot/meshes/visual/lowerArm_ascii.obj"/>
        </geometry>
      </visual>
    <!-- <visual>
        <origin xyz="0.0 0.0 0.0" rpy="0.0 0.0 0.0"/>
        <geometry>
          <sphere radius="0.02"/>
        </geometry>
      </visual> -->
    <!-- <visual>
        <origin xyz="0 0 -0.15" rpy="0.0 0.0 0.0"/>
        <geometry>
            <sphere radius="0.1"/>
        </geometry>
      </visual> -->
    </link>

    <link name="right_hand">
      <inertial>
        <origin xyz="0 0 0" rpy="0 0 0" />
        <mass value="0.5" />
        <inertia ixx="0.09" iyy="0.05" izz="0.07" ixy="0" ixz="0" iyz="0" />
      </inertial>
      <visual>
      <origin xyz="-0.02 0.0 0.02" rpy="0.0 0.0 0.0"/>
        <geometry>
          <mesh filename="../../../model/stanbot/meshes/visual/hand_ascii.obj"/>
        </geometry>
      </visual>
    <!-- <visual>
        <origin xyz="0.0 0.0 0.0" rpy="0.0 0.0 0.0"/>
        <geometry>
          <sphere radius="0.05"/>
        </geometry>
      </visual> -->
    </link>

    <link name="left_upper_arm">
      <inertial>
        <origin xyz="0 0 -0.15" rpy="0 0 0" />
        <mass value="0.5" />
        <inertia ixx="0.09" iyy="0.05" izz="0.07" ixy="0" ixz="0" iyz="0" />
      </inertial>
      <visual>
        <geometry>
          <mesh filename="../../../model/stanbot/meshes/visual/upperArm_ascii.obj"/>
        </geometry>
      </visual>
    </link>

    <link name="left_lower_arm">
      <inertial>
        <origin xyz="0 0 -0.15" rpy="0 0 0" />
        <mass value="0.5" />
        <inertia ixx="0.09" iyy="0.05" izz="0.07" ixy="0" ixz="0" iyz="0" />
      </inertial>
      <visual>
        <geometry>
          <mesh filename="../../../model/stanbot/meshes/visual/lowerArm_ascii.obj"/>
        </geometry>
      </visual>
    </link>

    <link name="left_hand">
      <inertial>
        <origin xyz="0 0 0" rpy="0 0 0" />
        <mass value="0.5" />
        <inertia ixx="0.09" iyy="0.05" izz="0.07" ixy="0" ixz="0" iyz="0" />
      </inertial>
      <visual>
        <origin xyz="0.02 0.0 0.02" rpy="0.0 0.0 3.1415"/>
        <geometry>
          <mesh filename="../../../model/stanbot/meshes/visual/hand_ascii.obj"/>
        </geometry>
      </visual>
    </link>

    <!-- Extraneous virtual links for spherical joints -->
    <link name="right_foot_ry">
      <inertial>
        <origin xyz="0 0 0" rpy="0 0 0" />
        <mass value="1e-10" />
        <inertia ixx="1e-10" iyy="1e-10" izz="1e-10" ixy="0" ixz="0" iyz="0" />
      </inertial>
    </link>

    <link name="left_foot_rx">
      <inertial>
        <origin xyz="0 0 0" rpy="0 0 0" />
        <mass value="1e-10" />
        <inertia ixx="1e-10" iyy="1e-10" izz="1e-10" ixy="0" ixz="0" iyz="0" />
      </inertial>
    </link>

    <link name="left_foot_ry">
      <inertial>
        <origin xyz="0 0 0" rpy="0 0 0" />
        <mass value="1e-10" />
        <inertia ixx="1e-10" iyy="1e-10" izz="1e-10" ixy="0" ixz="0" iyz="0" />
      </inertial>
    </link>

    <link name="right_hip_rx">
      <inertial>
        <origin xyz="0 0 0" rpy="0 0 0" />
        <mass value="1e-10" />
        <inertia ixx="1e-10" iyy="1e-10" izz="1e-10" ixy="0" ixz="0" iyz="0" />
      </inertial>
    </link>

    <link name="right_hip_ry">
      <inertial>
        <origin xyz="0 0 0" rpy="0 0 0" />
        <mass value="1e-10" />
        <inertia ixx="1e-10" iyy="1e-10" izz="1e-10" ixy="0" ixz="0" iyz="0" />
      </inertial>
    </link>

    <!-- <link name="right_hip_rz">
      <inertial>
        <origin xyz="0 0 0" rpy="0 0 0" />
        <mass value="1e-10" />
        <inertia ixx="1e-10" iyy="1e-10" izz="1e-10" ixy="0" ixz="0" iyz="0" />
      </inertial>
    </link> -->
<!-- 
    <link name="left_hip_rx">
      <inertial>
        <origin xyz="0 0 0" rpy="0 0 0" />
        <mass value="1e-10" />
        <inertia ixx="1e-10" iyy="1e-10" izz="1e-10" ixy="0" ixz="0" iyz="0" />
      </inertial>
    </link> -->

    <link name="left_hip_ry">
      <inertial>
        <origin xyz="0 0 0" rpy="0 0 0" />
        <mass value="1e-10" />
        <inertia ixx="1e-10" iyy="1e-10" izz="1e-10" ixy="0" ixz="0" iyz="0" />
      </inertial>
    </link>

    <link name="left_hip_rz">
      <inertial>
        <origin xyz="0 0 0" rpy="0 0 0" />
        <mass value="1e-10" />
        <inertia ixx="1e-10" iyy="1e-10" izz="1e-10" ixy="0" ixz="0" iyz="0" />
      </inertial>
      <!-- <visual>
        <origin xyz="0.0 0.0 0.0" rpy="0.0 0.0 0.0"/>
          <geometry>
            <sphere radius="0.1"/>
          </geometry>
      </visual> -->
    </link>

    <link name="right_shoulder_rx">
      <inertial>
        <origin xyz="0 0 0" rpy="0 0 0" />
        <mass value="1e-10" />
        <inertia ixx="1e-10" iyy="1e-10" izz="1e-10" ixy="0" ixz="0" iyz="0" />
      </inertial>
    <!-- <visual>
        <origin xyz="0.0 0.0 0.0" rpy="0.0 0.0 0.0"/>
          <geometry>
            <sphere radius="0.03"/>
          </geometry>
      </visual> -->
    </link>

    <link name="right_shoulder_ry">
      <inertial>
        <origin xyz="0 0 0" rpy="0 0 0" />
        <mass value="1e-10" />
        <inertia ixx="1e-10" iyy="1e-10" izz="1e-10" ixy="0" ixz="0" iyz="0" />
      </inertial>
    </link>

    <!-- <link name="right_shoulder_rz">
      <inertial>
        <origin xyz="0 0 0" rpy="0 0 0" />
        <mass value="1e-10" />
        <inertia ixx="1e-10" iyy="1e-10" izz="1e-10" ixy="0" ixz="0" iyz="0" />
      </inertial>
    </link> -->

    <link name="left_shoulder_rx">
      <inertial>
        <origin xyz="0 0 0" rpy="0 0 0" />
        <mass value="1e-10" />
        <inertia ixx="1e-10" iyy="1e-10" izz="1e-10" ixy="0" ixz="0" iyz="0" />
      </inertial>
    <!-- <visual>
        <origin xyz="0.0 0.0 0.0" rpy="0.0 0.0 0.0"/>
          <geometry>
            <sphere radius="0.03"/>
          </geometry>
      </visual> -->
    </link>

    <link name="left_shoulder_ry">
      <inertial>
        <origin xyz="0 0 0" rpy="0 0 0" />
        <mass value="1e-10" />
        <inertia ixx="1e-10" iyy="1e-10" izz="1e-10" ixy="0" ixz="0" iyz="0" />
      </inertial>
    </link>

    <!-- <link name="left_shoulder_rz">
      <inertial>
        <origin xyz="0 0 0" rpy="0 0 0" />
        <mass value="1e-10" />
        <inertia ixx="1e-10" iyy="1e-10" izz="1e-10" ixy="0" ixz="0" iyz="0" />
      </inertial>
    </link> -->

    <link name="right_hand_rx">
      <inertial>
        <origin xyz="0 0 0" rpy="0 0 0" />
        <mass value="1e-10" />
        <inertia ixx="1e-10" iyy="1e-10" izz="1e-10" ixy="0" ixz="0" iyz="0" />
      </inertial>
    </link>

    <link name="right_hand_ry">
      <inertial>
        <origin xyz="0 0 0" rpy="0 0 0" />
        <mass value="1e-10" />
        <inertia ixx="1e-10" iyy="1e-10" izz="1e-10" ixy="0" ixz="0" iyz="0" />
      </inertial>
    </link>

    <!-- <link name="right_hand_rz">
      <inertial>
        <origin xyz="0 0 0" rpy="0 0 0" />
        <mass value="1e-10" />
        <inertia ixx="1e-10" iyy="1e-10" izz="1e-10" ixy="0" ixz="0" iyz="0" />
      </inertial>
    </link> -->

    <link name="left_hand_rx">
      <inertial>
        <origin xyz="0 0 0" rpy="0 0 0" />
        <mass value="1e-10" />
        <inertia ixx="1e-10" iyy="1e-10" izz="1e-10" ixy="0" ixz="0" iyz="0" />
      </inertial>
    <!-- <visual>
        <origin xyz="0.0 0.0 0.0" rpy="0.0 0.0 0.0"/>
          <geometry>
            <sphere radius="0.05"/>
          </geometry>
      </visual> -->
    </link>

    <link name="left_hand_ry">
      <inertial>
        <origin xyz="0 0 0" rpy="0 0 0" />
        <mass value="1e-10" />
        <inertia ixx="1e-10" iyy="1e-10" izz="1e-10" ixy="0" ixz="0" iyz="0" />
      </inertial>
    </link>

    <!-- <link name="left_hand_rz">
      <inertial>
        <origin xyz="0 0 0" rpy="0 0 0" />
        <mass value="1e-10" />
        <inertia ixx="1e-10" iyy="1e-10" izz="1e-10" ixy="0" ixz="0" iyz="0" />
      </inertial>
    </link> -->

    <link name="head_rx">
      <inertial>
        <origin xyz="0 0 0" rpy="0 0 0" />
        <mass value="1e-10" />
        <inertia ixx="1e-10" iyy="1e-10" izz="1e-10" ixy="0" ixz="0" iyz="0" />
      </inertial>
    </link>

    <link name="head_ry">
      <inertial>
        <origin xyz="0 0 0" rpy="0 0 0" />
        <mass value="1e-10" />
        <inertia ixx="1e-10" iyy="1e-10" izz="1e-10" ixy="0" ixz="0" iyz="0" />
      </inertial>
    </link>

    <!-- Joints -->
    <!-- Right Leg -->
    <joint name="j0" type="revolute">
      <safety_controller k_position="100.0" k_velocity="40.0" soft_lower_limit="-2.8973" soft_upper_limit="2.8973"/>
      <origin rpy="0 0 0" xyz="0 0.03 0.02"/>
      <parent link="right_foot"/>
      <child link="right_foot_ry"/>
      <axis xyz="0 1 0"/>
      <calibration falling="0" />
      <limit effort="87" lower="-2.8973" upper="2.8973" velocity="2.1750"/>
    </joint>

    <joint name="j1" type="revolute">
      <safety_controller k_position="100.0" k_velocity="40.0" soft_lower_limit="-2.8973" soft_upper_limit="2.8973"/>
      <origin rpy="0 0 0" xyz="0 0 0"/>
      <parent link="right_foot_ry"/>
      <child link="right_calf"/>
      <axis xyz="1 0 0"/>
      <calibration falling="0" />
      <limit effort="87" lower="-2.8973" upper="2.8973" velocity="2.1750"/>
    </joint>

    <joint name="j2" type="revolute">
      <safety_controller k_position="100.0" k_velocity="40.0" soft_lower_limit="-1.7628" soft_upper_limit="1.7628"/>
      <origin rpy="0 0 0" xyz="0 0 0.4"/>
      <parent link="right_calf"/>
      <child link="right_thigh"/>
      <axis xyz="1 0 0"/>
      <calibration falling="45" />
      <limit effort="87" lower="-1.7628" upper="1.7628" velocity="2.1750"/>
    </joint>

    <joint name="j3" type="revolute">
      <safety_controller k_position="100.0" k_velocity="40.0" soft_lower_limit="-2.8973" soft_upper_limit="2.8973"/>
      <origin rpy="0 0 0" xyz="0 0 0.4"/>
      <parent link="right_thigh"/>
      <child link="right_hip_rx"/>
      <axis xyz="1 0 0"/>
      <limit effort="87" lower="-2.8973" upper="2.8973" velocity="2.1750"/>
    </joint>
    
    <joint name="j4" type="revolute">
      <safety_controller k_position="100.0" k_velocity="40.0" soft_lower_limit="-2.8973" soft_upper_limit="2.8973"/>
      <origin rpy="0 0 0" xyz="0 0 0"/>
      <parent link="right_hip_rx"/>
      <child link="right_hip_ry"/>
      <axis xyz="0 1 0"/>
      <limit effort="87" lower="-2.8973" upper="2.8973" velocity="2.1750"/>
    </joint>

    <joint name="j5" type="revolute">
      <safety_controller k_position="100.0" k_velocity="40.0" soft_lower_limit="-2.8973" soft_upper_limit="2.8973"/>
      <!-- <origin rpy="0 0 0" xyz="0.06 0 0.15"/> -->
      <origin rpy="0 0 0" xyz="0 0 0"/>
      <parent link="right_hip_ry"/>
      <child link="hip"/>
      <axis xyz="0 0 1"/>
      <limit effort="87" lower="-2.8973" upper="2.8973" velocity="2.1750"/>
    </joint>

    <!-- Left Leg -->
    <joint name="j6" type="revolute">
      <safety_controller k_position="100.0" k_velocity="40.0" soft_lower_limit="-3.0718" soft_upper_limit="-0.0698"/>
      <!-- <origin rpy="0 0 0" xyz="0.06 0 -0.15"/> -->
      <origin rpy="0 0 0" xyz="0.12 0 0"/>
      <parent link="hip"/>
      <child link="left_hip_rz"/>
      <axis xyz="0 0 1"/>
      <calibration falling="-125.0" />
      <limit effort="87" lower="-3.0718" upper="-0.0698" velocity="2.1750"/>
    </joint>

    <joint name="j7" type="revolute">
      <safety_controller k_position="100.0" k_velocity="40.0" soft_lower_limit="-3.0718" soft_upper_limit="-0.0698"/>
      <origin rpy="0 0 0" xyz="0 0 0"/>
      <parent link="left_hip_rz"/>
      <child link="left_hip_ry"/>
      <axis xyz="0 1 0"/>
      <calibration falling="-125.0" />
      <limit effort="87" lower="-3.0718" upper="-0.0698" velocity="2.1750"/>
    </joint>

    <joint name="j8" type="revolute">
      <safety_controller k_position="100.0" k_velocity="40.0" soft_lower_limit="-3.0718" soft_upper_limit="-0.0698"/>
      <origin rpy="0 0 0" xyz="0 0 0"/>
      <parent link="left_hip_ry"/>
      <child link="left_thigh"/>
      <axis xyz="1 0 0"/>
      <calibration falling="-125.0" />
      <limit effort="87" lower="-3.0718" upper="-0.0698" velocity="2.1750"/>
    </joint>

    <joint name="j9" type="revolute">
      <safety_controller k_position="100.0" k_velocity="40.0" soft_lower_limit="-2.8973" soft_upper_limit="2.8973"/>
      <origin rpy="0 0 0" xyz="0 0 -0.4"/>
      <parent link="left_thigh"/>
      <child link="left_calf"/>
      <axis xyz="1 0 0"/>
      <limit effort="12" lower="-2.8973" upper="2.8973" velocity="2.6100"/>
    </joint>

    <joint name="j10" type="revolute">
      <safety_controller k_position="100.0" k_velocity="40.0" soft_lower_limit="-0.0175" soft_upper_limit="3.7525"/>
      <!-- <origin rpy="0 0 0" xyz="0 -0.03 -0.22"/> -->
      <origin rpy="0 0 0" xyz="0 0 -0.4"/>
      <parent link="left_calf"/>
      <child link="left_foot_rx"/>
      <axis xyz="1 0 0"/>
      <calibration falling="80.0" />
      <limit effort="12" lower="-0.0175" upper="3.7525" velocity="2.6100"/>
    </joint>

    <joint name="j11" type="revolute">
      <safety_controller k_position="100.0" k_velocity="40.0" soft_lower_limit="-0.0175" soft_upper_limit="3.7525"/>
      <!-- <origin rpy="0 0 0" xyz="0 -0.03 -0.22"/> -->
      <origin rpy="0 0 0" xyz="0 0 0"/>
      <parent link="left_foot_rx"/>
      <child link="left_foot_ry"/>
      <axis xyz="0 1 0"/>
      <calibration falling="80.0" />
      <limit effort="12" lower="-0.0175" upper="3.7525" velocity="2.6100"/>
    </joint>

    <joint name="j12" type="revolute">
      <safety_controller k_position="100.0" k_velocity="40.0" soft_lower_limit="-0.0175" soft_upper_limit="3.7525"/>
      <!-- <origin rpy="0 0 0" xyz="0 -0.03 -0.22"/> -->
      <origin rpy="0 0 0" xyz="0 0 0"/>
      <parent link="left_foot_ry"/>
      <child link="left_foot"/>
      <axis xyz="0 0 1"/>
      <calibration falling="80.0" />
      <limit effort="12" lower="-0.0175" upper="3.7525" velocity="2.6100"/>
    </joint>

    <!-- Hip To Chest -->
    <joint name="j13" type="revolute">
      <safety_controller k_position="100.0" k_velocity="40.0" soft_lower_limit="-0.0175" soft_upper_limit="3.7525"/>
      <origin rpy="0 0 0" xyz="0.06 0 0.2"/>
      <parent link="hip"/>
      <child link="chest"/>
      <axis xyz="1 0 0"/>
      <calibration falling="80.0" />
      <limit effort="12" lower="-0.0175" upper="3.7525" velocity="2.6100"/>
    </joint>

    <!-- Right Arm -->
    <joint name="j14" type="revolute">
      <safety_controller k_position="100.0" k_velocity="40.0" soft_lower_limit="-2.8973" soft_upper_limit="2.8973"/>
      <origin rpy="0 0 0" xyz="-0.14 0 0.24"/>
      <parent link="chest"/>
      <child link="right_shoulder_rx"/>
      <axis xyz="1 0 0"/>
      <limit effort="12" lower="-2.8973" upper="2.8973" velocity="2.6100"/>
    </joint>

    <joint name="j15" type="revolute">
      <safety_controller k_position="100.0" k_velocity="40.0" soft_lower_limit="-2.8973" soft_upper_limit="2.8973"/>
      <origin rpy="0 0 0" xyz="0 0 0"/>
      <parent link="right_shoulder_rx"/>
      <child link="right_shoulder_ry"/>
      <axis xyz="0 1 0"/>
      <limit effort="12" lower="-2.8973" upper="2.8973" velocity="2.6100"/>
    </joint>

    <joint name="j16" type="revolute">
      <safety_controller k_position="100.0" k_velocity="40.0" soft_lower_limit="-2.8973" soft_upper_limit="2.8973"/>
      <origin rpy="0 0 0" xyz="0 0 0"/>
      <parent link="right_shoulder_ry"/>
      <child link="right_upper_arm"/>
      <axis xyz="0 0 1"/>
      <limit effort="12" lower="-2.8973" upper="2.8973" velocity="2.6100"/>
    </joint>

    <joint name="j17" type="revolute">
      <safety_controller k_position="100.0" k_velocity="40.0" soft_lower_limit="-2.8973" soft_upper_limit="2.8973"/>
      <origin rpy="0 0 0" xyz="0 0 -0.3"/>
      <parent link="right_upper_arm"/>
      <child link="right_lower_arm"/>
      <axis xyz="1 0 0"/>
      <limit effort="12" lower="-2.8973" upper="2.8973" velocity="2.6100"/>
    </joint>

    <joint name="j18" type="revolute">
      <safety_controller k_position="100.0" k_velocity="40.0" soft_lower_limit="-2.8973" soft_upper_limit="2.8973"/>
      <origin rpy="0 0 0" xyz="0 0 -0.3"/>
      <parent link="right_lower_arm"/>
      <child link="right_hand_rx"/>
      <axis xyz="1 0 0"/>
      <limit effort="12" lower="-2.8973" upper="2.8973" velocity="2.6100"/>
    </joint>

    <joint name="j19" type="revolute">
      <safety_controller k_position="100.0" k_velocity="40.0" soft_lower_limit="-2.8973" soft_upper_limit="2.8973"/>
      <origin rpy="0 0 0" xyz="0 0 0"/>
      <parent link="right_hand_rx"/>
      <child link="right_hand_ry"/>
      <axis xyz="0 1 0"/>
      <limit effort="12" lower="-2.8973" upper="2.8973" velocity="2.6100"/>
    </joint>

    <joint name="j20" type="revolute">
      <safety_controller k_position="100.0" k_velocity="40.0" soft_lower_limit="-2.8973" soft_upper_limit="2.8973"/>
      <origin rpy="0 0 0" xyz="0 0 0"/>
      <parent link="right_hand_ry"/>
      <child link="right_hand"/>
      <axis xyz="0 0 1"/>
      <limit effort="12" lower="-2.8973" upper="2.8973" velocity="2.6100"/>
    </joint>

    <!-- Left Arm -->
    <joint name="j21" type="revolute">
      <safety_controller k_position="100.0" k_velocity="40.0" soft_lower_limit="-2.8973" soft_upper_limit="2.8973"/>
      <origin rpy="0 0 0" xyz="0.14 0 0.24"/>
      <parent link="chest"/>
      <child link="left_shoulder_rx"/>
      <axis xyz="1 0 0"/>
      <limit effort="12" lower="-2.8973" upper="2.8973" velocity="2.6100"/>
    </joint>

    <joint name="j22" type="revolute">
      <safety_controller k_position="100.0" k_velocity="40.0" soft_lower_limit="-2.8973" soft_upper_limit="2.8973"/>
      <origin rpy="0 0 0" xyz="0 0 0"/>
      <parent link="left_shoulder_rx"/>
      <child link="left_shoulder_ry"/>
      <axis xyz="0 1 0"/>
      <limit effort="12" lower="-2.8973" upper="2.8973" velocity="2.6100"/>
    </joint>

    <joint name="j23" type="revolute">
      <safety_controller k_position="100.0" k_velocity="40.0" soft_lower_limit="-2.8973" soft_upper_limit="2.8973"/>
      <origin rpy="0 0 0" xyz="0 0 0"/>
      <parent link="left_shoulder_ry"/>
      <child link="left_upper_arm"/>
      <axis xyz="0 0 1"/>
      <limit effort="12" lower="-2.8973" upper="2.8973" velocity="2.6100"/>
    </joint>

    <joint name="j24" type="revolute">
      <safety_controller k_position="100.0" k_velocity="40.0" soft_lower_limit="-2.8973" soft_upper_limit="2.8973"/>
      <origin rpy="0 0 0" xyz="0 0 -0.3"/>
      <parent link="left_upper_arm"/>
      <child link="left_lower_arm"/>
      <axis xyz="1 0 0"/>
      <limit effort="12" lower="-2.8973" upper="2.8973" velocity="2.6100"/>
    </joint>

    <joint name="j25" type="revolute">
      <safety_controller k_position="100.0" k_velocity="40.0" soft_lower_limit="-2.8973" soft_upper_limit="2.8973"/>
      <origin rpy="0 0 0" xyz="0 0 -0.3"/>
      <parent link="left_lower_arm"/>
      <child link="left_hand_rx"/>
      <axis xyz="1 0 0"/>
      <limit effort="12" lower="-2.8973" upper="2.8973" velocity="2.6100"/>
    </joint>

    <joint name="j26" type="revolute">
      <safety_controller k_position="100.0" k_velocity="40.0" soft_lower_limit="-2.8973" soft_upper_limit="2.8973"/>
      <origin rpy="0 0 0" xyz="0 0 0"/>
      <parent link="left_hand_rx"/>
      <child link="left_hand_ry"/>
      <axis xyz="0 1 0"/>
      <limit effort="12" lower="-2.8973" upper="2.8973" velocity="2.6100"/>
    </joint>

    <joint name="j27" type="revolute">
      <safety_controller k_position="100.0" k_velocity="40.0" soft_lower_limit="-2.8973" soft_upper_limit="2.8973"/>
      <origin rpy="0 0 0" xyz="0 0 0"/>
      <parent link="left_hand_ry"/>
      <child link="left_hand"/>
      <axis xyz="0 0 1"/>
      <limit effort="12" lower="-2.8973" upper="2.8973" velocity="2.6100"/>
    </joint>

    <joint name="j28" type="revolute">
      <safety_controller k_position="100.0" k_velocity="40.0" soft_lower_limit="-2.8973" soft_upper_limit="2.8973"/>
      <origin rpy="0 0 0" xyz="0 0 0.30"/>
      <parent link="chest"/>
      <child link="head_rx"/>
      <axis xyz="1 0 0"/>
      <limit effort="12" lower="-2.8973" upper="2.8973" velocity="2.6100"/>
    </joint>

    <joint name="j29" type="revolute">
      <safety_controller k_position="100.0" k_velocity="40.0" soft_lower_limit="-2.8973" soft_upper_limit="2.8973"/>
      <origin rpy="0 0 0" xyz="0 0 0"/>
      <parent link="head_rx"/>
      <child link="head_ry"/>
      <axis xyz="0 1 0"/>
      <limit effort="12" lower="-2.8973" upper="2.8973" velocity="2.6100"/>
    </joint>
    
    <joint name="j30" type="revolute">
      <safety_controller k_position="100.0" k_velocity="40.0" soft_lower_limit="-2.8973" soft_upper_limit="2.8973"/>
      <origin rpy="0 0 0" xyz="0 0 0"/>
      <parent link="head_ry"/>
      <child link="head"/>
      <axis xyz="0 0 1"/>
      <limit effort="12" lower="-2.8973" upper="2.8973" velocity="2.6100"/>
    </joint>

</robot>
